Using cuda device
Logging to ppo_picking_sb3/ppo_sb3_1
/home/kpatherya3/anaconda3/envs/causal_env/lib/python3.7/site-packages/stable_baselines3/common/callbacks.py:337: UserWarning: Training and eval env are not of the same type<stable_baselines3.common.vec_env.vec_monitor.VecMonitor object at 0x7ff634c3a410> != <stable_baselines3.common.vec_env.dummy_vec_env.DummyVecEnv object at 0x7ff634a47490>
  warnings.warn("Training and eval env are not of the same type" f"{self.training_env} != {self.eval_env}")
Traceback (most recent call last):
  File "ppo_vanilla.py", line 298, in <module>
    main()
  File "ppo_vanilla.py", line 220, in main
    wandb_config=wandb_config
  File "ppo_vanilla.py", line 162, in train_policy
    tb_log_name="ppo_sb3"
  File "/home/kpatherya3/anaconda3/envs/causal_env/lib/python3.7/site-packages/stable_baselines3/ppo/ppo.py", line 308, in learn
    reset_num_timesteps=reset_num_timesteps,
  File "/home/kpatherya3/anaconda3/envs/causal_env/lib/python3.7/site-packages/stable_baselines3/common/on_policy_algorithm.py", line 250, in learn
    continue_training = self.collect_rollouts(self.env, callback, self.rollout_buffer, n_rollout_steps=self.n_steps)
  File "/home/kpatherya3/anaconda3/envs/causal_env/lib/python3.7/site-packages/stable_baselines3/common/on_policy_algorithm.py", line 178, in collect_rollouts
    new_obs, rewards, dones, infos = env.step(clipped_actions)
  File "/home/kpatherya3/anaconda3/envs/causal_env/lib/python3.7/site-packages/stable_baselines3/common/vec_env/base_vec_env.py", line 162, in step
    return self.step_wait()
  File "/home/kpatherya3/anaconda3/envs/causal_env/lib/python3.7/site-packages/stable_baselines3/common/vec_env/vec_monitor.py", line 76, in step_wait
    obs, rewards, dones, infos = self.venv.step_wait()
  File "/home/kpatherya3/anaconda3/envs/causal_env/lib/python3.7/site-packages/stable_baselines3/common/vec_env/subproc_vec_env.py", line 120, in step_wait
    results = [remote.recv() for remote in self.remotes]
  File "/home/kpatherya3/anaconda3/envs/causal_env/lib/python3.7/site-packages/stable_baselines3/common/vec_env/subproc_vec_env.py", line 120, in <listcomp>
    results = [remote.recv() for remote in self.remotes]
  File "/home/kpatherya3/anaconda3/envs/causal_env/lib/python3.7/multiprocessing/connection.py", line 250, in recv
    buf = self._recv_bytes()
  File "/home/kpatherya3/anaconda3/envs/causal_env/lib/python3.7/multiprocessing/connection.py", line 407, in _recv_bytes
    buf = self._recv(4)
  File "/home/kpatherya3/anaconda3/envs/causal_env/lib/python3.7/multiprocessing/connection.py", line 383, in _recv
    raise EOFError
EOFError
