Traceback (most recent call last):
  File "ppo_pushing_curr_basic.py", line 207, in <module>
    main()
  File "ppo_pushing_curr_basic.py", line 203, in main
    wandb_config=wandb_config
  File "ppo_pushing_curr_basic.py", line 121, in train_with_curriculum
    model = PPO.load(pretrained_path, env=env, policy_kwargs=policy_kwargs, tensorboard_log=log_dir, seed=seed, **ppo_config)
  File "/home/kpatherya3/anaconda3/envs/causal_env/lib/python3.7/site-packages/stable_baselines3/common/base_class.py", line 688, in load
    path, device=device, custom_objects=custom_objects, print_system_info=print_system_info
  File "/home/kpatherya3/anaconda3/envs/causal_env/lib/python3.7/site-packages/stable_baselines3/common/save_util.py", line 388, in load_from_zip_file
    load_path = open_path(load_path, "r", verbose=verbose, suffix="zip")
  File "/home/kpatherya3/anaconda3/envs/causal_env/lib/python3.7/functools.py", line 840, in wrapper
    return dispatch(args[0].__class__)(*args, **kw)
  File "/home/kpatherya3/anaconda3/envs/causal_env/lib/python3.7/site-packages/stable_baselines3/common/save_util.py", line 232, in open_path_str
    return open_path(pathlib.Path(path), mode, verbose, suffix)
  File "/home/kpatherya3/anaconda3/envs/causal_env/lib/python3.7/functools.py", line 840, in wrapper
    return dispatch(args[0].__class__)(*args, **kw)
  File "/home/kpatherya3/anaconda3/envs/causal_env/lib/python3.7/site-packages/stable_baselines3/common/save_util.py", line 284, in open_path_pathlib
    return open_path(path, mode, verbose, suffix)
  File "/home/kpatherya3/anaconda3/envs/causal_env/lib/python3.7/functools.py", line 840, in wrapper
    return dispatch(args[0].__class__)(*args, **kw)
  File "/home/kpatherya3/anaconda3/envs/causal_env/lib/python3.7/site-packages/stable_baselines3/common/save_util.py", line 264, in open_path_pathlib
    raise error
  File "/home/kpatherya3/anaconda3/envs/causal_env/lib/python3.7/site-packages/stable_baselines3/common/save_util.py", line 256, in open_path_pathlib
    path = path.open("rb")
  File "/home/kpatherya3/anaconda3/envs/causal_env/lib/python3.7/pathlib.py", line 1208, in open
    opener=self._opener)
  File "/home/kpatherya3/anaconda3/envs/causal_env/lib/python3.7/pathlib.py", line 1063, in _opener
    return self._accessor.open(self, flags, mode)
FileNotFoundError: [Errno 2] No such file or directory: '../ppo_pushing_sb3/final_model.zip.zip'
